Exception during training: 'train'
Traceback (most recent call last):
  File "/opt/program/train", line 48, in train
    inputdata_dic['train'],
KeyError: 'train'
